<?xml version="1.0" ?>
<robot name="robotRR">
    <!-- link list -->
    <link name="base_link">
      <gravity>0</gravity>
        <visual>
            <origin rpy="0 0 0" xyz="0 0 0" />
            <geometry>
                <mesh filename="package://irm3_ros_robot_description_pkg/meshes/base.stl" />
            </geometry>
            <material name="">
                <color rgba="0.7372549 0.3490196 0.1607843 1" />
            </material>
        </visual>
        <collision>
            <origin rpy="0 0 0" xyz="0 0 0" />
            <geometry>
                <mesh filename="package://irm3_ros_robot_description_pkg/meshes/base.stl" />
            </geometry>
            <material name="">
                <color rgba="1 1 0 1" />
            </material>
        </collision>
        
<inertial>
            <mass value="6.215" />
            <origin rpy="0 0 0" xyz="-0.04204 8.01E-05 0.07964" />
            <inertia ixx="0.0247272" ixy="-8.0784E-05" ixz="0.00130902" iyy="0.0491285" iyz="-8.0419E-06" izz="0.0472376" />
        </inertial>

    </link>
    <link name="link_1">
      <gravity>0</gravity>
        
<inertial>
            <mass value="3.067" />
            <origin rpy="0 0 0" xyz="9.77E-05 -0.00012 0.23841" />
            <inertia ixx="0.0142175" ixy="-1.28579E-05" ixz="-2.31364E-05" iyy="0.0144041" iyz="1.93404E-05" izz="0.0104533" />
        </inertial>

        <visual>
            <origin rpy="0 0 0" xyz="0 0 0" />
            <geometry>
                <mesh filename="package://irm3_ros_robot_description_pkg/meshes/RobotRR.stl" />
            </geometry>
            <material name="">
                <color rgba="0.7372549 0.3490196 0.1607843 1" />
            </material>
        </visual>
        <collision>
            <origin rpy="0 0 0" xyz="0 0 0" />
            <geometry>
                <mesh filename="package://irm3_ros_robot_description_pkg/meshes/RobotRR.stl" />
            </geometry>
            <material name="">
                <color rgba="1 1 0 1" />
            </material>
        </collision>
    </link>
    <link name="link_2">
      <gravity>0</gravity>
        
<inertial>
            <mass value="3.909" />
            <origin rpy="1.57295 0 0" xyz="0 0 0" />
            <inertia ixx="0.0603111" ixy="9.83431E-06" ixz="5.72407E-05" iyy="0.041569" iyz="-0.00050497" izz="0.0259548" />
        </inertial>

        <visual>
            <origin rpy="1.57295 0 0" xyz="0 0 0" />
            <geometry>
                <mesh filename="package://irm3_ros_robot_description_pkg/meshes/RobotRR.stl" />
            </geometry>
            <material name="">
                <color rgba="0.7372549 0.3490196 0.1607843 1" />
            </material>
        </visual>
        <collision>
            <origin rpy="1.57295 0 0" xyz="0 0 0" />
            <geometry>
                <mesh filename="package://irm3_ros_robot_description_pkg/meshes/RobotRR.stl" />
            </geometry>
            <material name="">
                <color rgba="1 1 0 1" />
            </material>
        </collision>
    </link>
    <link name="tool0_link" />
    <!-- end of link list -->
    <!-- joint list -->
    <joint name="joint_1" type="revolute">
        <origin rpy="0 0 0" xyz="0 0 0" />
        <parent link="base_link" />
        <child link="link_1" />
        <limit effort="300" lower="-6" upper="6" velocity="4.36332" />
        <axis xyz="0 1 0" />
        <dynamics damping="0.0" friction="0.0" />
    </joint>
    <joint name="joint_2" type="revolute">
        <origin rpy="0 0 0" xyz="1 0 0" />
        <parent link="link_1" />
        <child link="link_2" />
        <limit effort="300" lower="-4" upper="4" velocity="4.36332" />
        <axis xyz="0 1 0" />
        <dynamics damping="0.0" friction="0.0" />
    </joint>
    <joint name="joint3-tool0" type="fixed">
        <parent link="link_2" />
        <child link="tool0_link" />
        <origin rpy="0 0 0" xyz="0 0 0" />
    </joint>
    <!-- end of joint list -->
    <!-- ROS base_link to ABB World Coordinates transform -->
    <link name="base" />
    <joint name="base_link-base" type="fixed">
        <origin rpy="0 0 0" xyz="0 0 1" />
        <parent link="base" />
        <child link="base_link" />
    </joint>
    
<transmission name="trans_joint_1">
        <type>transmission_interface/SimpleTransmission</type>
        <joint name="joint_1">
            <hardwareInterface>hardware_interface/EffortJointInterface</hardwareInterface>
        </joint>
        <actuator name="joint_1_motor">
            <hardwareInterface>hardware_interface/EffortJointInterface</hardwareInterface>
            <mechanicalReduction>1</mechanicalReduction>
        </actuator>
    </transmission>
    <transmission name="trans_joint_2">
        <type>transmission_interface/SimpleTransmission</type>
        <joint name="joint_2">
            <hardwareInterface>hardware_interface/EffortJointInterface</hardwareInterface>
        </joint>
        <actuator name="joint_2_motor">
            <hardwareInterface>hardware_interface/EffortJointInterface</hardwareInterface>
            <mechanicalReduction>1</mechanicalReduction>
        </actuator>
    </transmission>
    <gazebo>
        <plugin name="gazebo_ros_control" filename="libgazebo_ros_control.so">
            <robotNamespace>/</robotNamespace>
        </plugin>
    </gazebo>
</robot>
