<?xml version="1.0" ?>
<robot name="robotRR">
  <link name="world"/>
  <joint name="world-base_link-fixed" type="fixed">
  <parent link="world"/>
  <child link="base"/>
  </joint>
  
    <!-- link list -->
    <link name="base_link">
        <visual>
            <origin rpy="0 0 0" xyz="0 0 0" />
            <geometry>
                <mesh filename="package://irm3_ros_robot_description_pkg/meshes/base.stl" />
            </geometry>
            <material name="">
                <color rgba="0.7372549 0.3490196 0.1607843 1" />
            </material>
        </visual>
        <collision>
            <origin rpy="0 0 0" xyz="0 0 0" />
            <geometry>
                <mesh filename="package://irm3_ros_robot_description_pkg/meshes/base.stl" />
            </geometry>
            <material name="">
                <color rgba="1 1 0 1" />
            </material>
        </collision>
        
<inertial>
            <mass value="6.215" />
            <origin rpy="0 0 0" xyz="-0.04204 8.01E-05 0.07964" />
            <inertia ixx="0.0247272" ixy="-8.0784E-05" ixz="0.00130902" iyy="0.0491285" iyz="-8.0419E-06" izz="0.0472376" />
        </inertial>

    </link>
    <link name="link_1">
        
<inertial>
            <mass value="3.067" />
            <origin rpy="0 0 0" xyz="9.77E-05 -0.00012 0.23841" />
            <inertia ixx="0.0142175" ixy="-1.28579E-05" ixz="-2.31364E-05" iyy="0.0144041" iyz="1.93404E-05" izz="0.0104533" />
        </inertial>

        <visual>
            <origin rpy="0 0 0" xyz="0 0 0" />
            <geometry>
                <mesh filename="package://irm3_ros_robot_description_pkg/meshes/RobotRR.stl" />
            </geometry>
            <material name="">
                <color rgba="0.7372549 0.3490196 0.1607843 1" />
            </material>
        </visual>
        <collision>
            <origin rpy="0 0 0" xyz="0 0 0" />
            <geometry>
                <mesh filename="package://irm3_ros_robot_description_pkg/meshes/RobotRR.stl" />
            </geometry>
            <material name="">
                <color rgba="1 1 0 1" />
            </material>
        </collision>
    </link>
    <link name="link_2">
        
<inertial>
            <mass value="3.909" />
            <origin rpy="1.57295 0 0" xyz="0 0 0" />
            <inertia ixx="0.0603111" ixy="9.83431E-06" ixz="5.72407E-05" iyy="0.041569" iyz="-0.00050497" izz="0.0259548" />
        </inertial>

        <visual>
            <origin rpy="1.57295 0 0" xyz="0 0 0" />
            <geometry>
                <mesh filename="package://irm3_ros_robot_description_pkg/meshes/RobotRR.stl" />
            </geometry>
            <material name="">
                <color rgba="0.7372549 0.3490196 0.1607843 1" />
            </material>
        </visual>
        <collision>
            <origin rpy="1.57295 0 0" xyz="0 0 0" />
            <geometry>
                <mesh filename="package://irm3_ros_robot_description_pkg/meshes/RobotRR.stl" />
            </geometry>
            <material name="">
                <color rgba="1 1 0 1" />
            </material>
        </collision>
    </link>
    <link name="tool0_link">
        <gravity>0</gravity>
    </link>
    <!-- end of link list -->
    <!-- joint list -->
    <joint name="joint_1" type="revolute">
        <origin rpy="0 0 0" xyz="0 0 0" />
        <parent link="base_link" />
        <child link="link_1" />
        <limit effort="300" lower="-6" upper="6" velocity="4.36332" />
        <axis xyz="0 1 0" />
        <dynamics damping="0.7" friction="0.0" />
    </joint>
    <joint name="joint_2" type="revolute">
        <origin rpy="0 0 0" xyz="1 0 0" />
        <parent link="link_1" />
        <child link="link_2" />
        <limit effort="300" lower="-4" upper="4" velocity="4.36332" />
        <axis xyz="0 1 0" />
        <dynamics damping="0.7" friction="0.0" />
    </joint>
    <joint name="joint3-tool0" type="fixed">
        <parent link="link_2" />
        <child link="tool0_link" />
        <origin rpy="0 0 0" xyz="0 0 0" />
    </joint>
    <!-- end of joint list -->
    <!-- ROS base_link to ABB World Coordinates transform -->
    <link name="base">
        <origin rpy="0 0 0" xyz="0 0 0" />
    </link>
    <joint name="base_link-base" type="fixed">
        <origin rpy="0 0 0" xyz="0 0 1" />
        <parent link="base" />
        <child link="base_link" />
    </joint>
    

    <transmission name="trans_joint_1">
        <type>transmission_interface/SimpleTransmission</type>
        <joint name="joint_1"/>
        <actuator name="joint_1_motor">
            <hardwareInterface>EffortJointInterface</hardwareInterface>
            <mechanicalReduction>1</mechanicalReduction>
        </actuator>
    </transmission>
    <transmission name="trans_joint_2">
        <type>transmission_interface/SimpleTransmission</type>
        <joint name="joint_2"/>
        <actuator name="joint_2_motor">
            <hardwareInterface>EffortJointInterface</hardwareInterface>
            <mechanicalReduction>1</mechanicalReduction>
        </actuator>
    </transmission>

      <!-- ros_control plugin -->
  <gazebo>
    <plugin name="gazebo_ros_control" filename="libgazebo_ros_control.so">
      <robotNamespace>/robotRR</robotNamespace>
      <robotSimType>gazebo_ros_control/DefaultRobotHWSim</robotSimType>
      <legacyModeNS>true</legacyModeNS>
    </plugin>
  </gazebo>

  <!-- Link1 -->
  <gazebo reference="base_link">
    <material>Gazebo/Orange</material>
  </gazebo>

  <!-- Link2 -->
  <gazebo reference="link_1">
    <mu1>0.2</mu1>
    <mu2>0.2</mu2>
    <material>Gazebo/Black</material>
  </gazebo>
  
  <gazebo reference="link_2">
    <mu1>0.2</mu1>
    <mu2>0.2</mu2>
    <material>Gazebo/Black</material>
  </gazebo>
  

  
</robot>
